{
  "name": "Genesis Chamber",
  "blocks": [
    { "x": 0, "y": 0, "z": 0, "type": "cobblestone" },
    { "x": 1, "y": 0, "z": 0, "type": "cobblestone" },
    { "x": 2, "y": 0, "z": 0, "type": "cobblestone" },
    { "x": 3, "y": 0, "z": 0, "type": "cobblestone" },
    { "x": 4, "y": 0, "z": 0, "type": "cobblestone" },
    { "x": 0, "y": 0, "z": 1, "type": "cobblestone" },
    { "x": 1, "y": 0, "z": 1, "type": "oak_planks" },
    { "x": 2, "y": 0, "z": 1, "type": "oak_planks" },
    { "x": 3, "y": 0, "z": 1, "type": "oak_planks" },
    { "x": 4, "y": 0, "z": 1, "type": "cobblestone" },
    { "x": 0, "y": 0, "z": 2, "type": "cobblestone" },
    { "x": 1, "y": 0, "z": 2, "type": "oak_planks" },
    { "x": 2, "y": 0, "z": 2, "type": "oak_planks" },
    { "x": 3, "y": 0, "z": 2, "type": "oak_planks" },
    { "x": 4, "y": 0, "z": 2, "type": "cobblestone" },
    { "x": 0, "y": 0, "z": 3, "type": "cobblestone" },
    { "x": 1, "y": 0, "z": 3, "type": "oak_planks" },
    { "x": 2, "y": 0, "z": 3, "type": "oak_planks" },
    { "x": 3, "y": 0, "z": 3, "type": "oak_planks" },
    { "x": 4, "y": 0, "z": 3, "type": "cobblestone" },
    { "x": 0, "y": 0, "z": 4, "type": "cobblestone" },
    { "x": 1, "y": 0, "z": 4, "type": "cobblestone" },
    { "x": 2, "y": 0, "z": 4, "type": "cobblestone" },
    { "x": 3, "y": 0, "z": 4, "type": "cobblestone" },
    { "x": 4, "y": 0, "z": 4, "type": "cobblestone" },
    { "x": 0, "y": 1, "z": 0, "type": "cobblestone" },
    { "x": 4, "y": 1, "z": 0, "type": "cobblestone" },
    { "x": 0, "y": 1, "z": 1, "type": "crafting_table" },
    { "x": 0, "y": 1, "z": 2, "type": "furnace" },
    { "x": 0, "y": 1, "z": 3, "type": "chest" },
    { "x": 0, "y": 1, "z": 4, "type": "cobblestone" },
    { "x": 2, "y": 1, "z": 4, "type": "oak_door" },
    { "x": 4, "y": 1, "z": 4, "type": "cobblestone" },
    { "x": 4, "y": 1, "z": 1, "type": "cobblestone" },
    { "x": 4, "y": 1, "z": 2, "type": "cobblestone" },
    { "x": 4, "y": 1, "z": 3, "type": "cobblestone" },
    { "x": 0, "y": 2, "z": 0, "type": "cobblestone" },
    { "x": 1, "y": 2, "z": 0, "type": "cobblestone" },
    { "x": 2, "y": 2, "z": 0, "type": "cobblestone" },
    { "x": 3, "y": 2, "z": 0, "type": "cobblestone" },
    { "x": 4, "y": 2, "z": 0, "type": "cobblestone" },
    { "x": 0, "y": 2, "z": 1, "type": "cobblestone" },
    { "x": 0, "y": 2, "z": 2, "type": "cobblestone" },
    { "x": 0, "y": 2, "z": 3, "type": "cobblestone" },
    { "x": 0, "y": 2, "z": 4, "type": "cobblestone" },
    { "x": 1, "y": 2, "z": 4, "type": "cobblestone" },
    { "x": 2, "y": 2, "z": 4, "type": "air" },
    { "x": 3, "y": 2, "z": 4, "type": "cobblestone" },
    { "x": 4, "y": 2, "z": 4, "type": "cobblestone" },
    { "x": 4, "y": 2, "z": 1, "type": "cobblestone" },
    { "x": 4, "y": 2, "z": 2, "type": "cobblestone" },
    { "x": 4, "y": 2, "z": 3, "type": "cobblestone" },
    { "x": 0, "y": 3, "z": 0, "type": "cobblestone" },
    { "x": 1, "y": 3, "z": 0, "type": "cobblestone" },
    { "x": 2, "y": 3, "z": 0, "type": "cobblestone" },
    { "x": 3, "y": 3, "z": 0, "type": "cobblestone" },
    { "x": 4, "y": 3, "z": 0, "type": "cobblestone" }
  ],
  "starter_kit": [{ "item": "oak_log", "count": 3 }]
}