{
  "small_hut": {
    "name": "Small Hut",
    "description": "A cozy 4x4 starter hut made of wood and cobblestone, perfect for a first night.",
    "blocks": [
      { "x": 0, "y": 0, "z": 0, "type": "oak_log" }, { "x": 3, "y": 0, "z": 0, "type": "oak_log" }, { "x": 0, "y": 0, "z": 3, "type": "oak_log" }, { "x": 3, "y": 0, "z": 3, "type": "oak_log" },
      { "x": 1, "y": 0, "z": 0, "type": "cobblestone" }, { "x": 2, "y": 0, "z": 0, "type": "cobblestone" },
      { "x": 0, "y": 0, "z": 1, "type": "oak_planks" }, { "x": 0, "y": 0, "z": 2, "type": "oak_planks" },
      { "x": 3, "y": 0, "z": 1, "type": "oak_planks" }, { "x": 3, "y": 0, "z": 2, "type": "oak_planks" },
      { "x": 1, "y": 0, "z": 3, "type": "oak_planks" }, { "x": 2, "y": 0, "z": 3, "type": "oak_planks" },
      { "x": 0, "y": 1, "z": 0, "type": "oak_log" }, { "x": 3, "y": 1, "z": 0, "type": "oak_log" }, { "x": 0, "y": 1, "z": 3, "type": "oak_log" }, { "x": 3, "y": 1, "z": 3, "type": "oak_log" },
      { "x": 1, "y": 1, "z": 0, "type": "glass" }, { "x": 2, "y": 1, "z": 0, "type": "glass" },
      { "x": 0, "y": 1, "z": 1, "type": "oak_planks" }, { "x": 0, "y": 1, "z": 2, "type": "oak_planks" },
      { "x": 3, "y": 1, "z": 1, "type": "oak_planks" }, { "x": 3, "y": 1, "z": 2, "type": "oak_planks" },
      { "x": 0, "y": 2, "z": 0, "type": "oak_log" }, { "x": 3, "y": 2, "z": 0, "type": "oak_log" }, { "x": 0, "y": 2, "z": 3, "type": "oak_log" }, { "x": 3, "y": 2, "z": 3, "type": "oak_log" },
      { "x": 1, "y": 2, "z": 0, "type": "cobblestone" }, { "x": 2, "y": 2, "z": 0, "type": "cobblestone" },
      { "x": 1, "y": 2, "z": 3, "type": "cobblestone" }, { "x": 2, "y": 2, "z": 3, "type": "cobblestone" },
      { "x": 0, "y": 2, "z": 1, "type": "cobblestone" }, { "x": 0, "y": 2, "z": 2, "type": "cobblestone" },
      { "x": 3, "y": 2, "z": 1, "type": "cobblestone" }, { "x": 3, "y": 2, "z": 2, "type": "cobblestone" },
      { "x": 0, "y": 3, "z": 0, "type": "oak_stairs" }, { "x": 1, "y": 3, "z": 0, "type": "oak_stairs" }, { "x": 2, "y": 3, "z": 0, "type": "oak_stairs" }, { "x": 3, "y": 3, "z": 0, "type": "oak_stairs" }
    ]
  },
  "night_bunker": {
    "name": "Night Bunker",
    "description": "A quick 3x3 dirt shelter with a doorway, built for fast nighttime cover.",
    "blocks": [
      { "x": 0, "y": 0, "z": 0, "type": "dirt" }, { "x": 1, "y": 0, "z": 0, "type": "dirt" }, { "x": 2, "y": 0, "z": 0, "type": "dirt" },
      { "x": 0, "y": 0, "z": 1, "type": "dirt" }, { "x": 1, "y": 0, "z": 1, "type": "dirt" }, { "x": 2, "y": 0, "z": 1, "type": "dirt" },
      { "x": 0, "y": 0, "z": 2, "type": "dirt" }, { "x": 1, "y": 0, "z": 2, "type": "dirt" }, { "x": 2, "y": 0, "z": 2, "type": "dirt" },
      { "x": 0, "y": 1, "z": 0, "type": "dirt" }, { "x": 1, "y": 1, "z": 0, "type": "dirt" }, { "x": 2, "y": 1, "z": 0, "type": "dirt" },
      { "x": 0, "y": 1, "z": 1, "type": "dirt" }, { "x": 2, "y": 1, "z": 1, "type": "dirt" },
      { "x": 0, "y": 1, "z": 2, "type": "dirt" }, { "x": 1, "y": 1, "z": 2, "type": "dirt" }, { "x": 2, "y": 1, "z": 2, "type": "dirt" },
      { "x": 0, "y": 2, "z": 0, "type": "dirt" }, { "x": 1, "y": 2, "z": 0, "type": "dirt" }, { "x": 2, "y": 2, "z": 0, "type": "dirt" },
      { "x": 0, "y": 2, "z": 1, "type": "dirt" }, { "x": 1, "y": 2, "z": 1, "type": "dirt" }, { "x": 2, "y": 2, "z": 1, "type": "dirt" },
      { "x": 0, "y": 2, "z": 2, "type": "dirt" }, { "x": 1, "y": 2, "z": 2, "type": "dirt" }, { "x": 2, "y": 2, "z": 2, "type": "dirt" }
    ]
  },
  "watchtower": {
    "name": "Simple Watchtower",
    "description": "A 3x3 cobblestone watchtower to help you see approaching dangers.",
    "blocks": [
      { "x": 0, "y": 0, "z": 0, "type": "cobblestone" }, { "x": 1, "y": 0, "z": 0, "type": "cobblestone" }, { "x": 2, "y": 0, "z": 0, "type": "cobblestone" },
      { "x": 0, "y": 0, "z": 1, "type": "cobblestone" }, { "x": 2, "y": 0, "z": 1, "type": "cobblestone" },
      { "x": 0, "y": 0, "z": 2, "type": "cobblestone" }, { "x": 1, "y": 0, "z": 2, "type": "cobblestone" }, { "x": 2, "y": 0, "z": 2, "type": "cobblestone" },
      { "x": 1, "y": 1, "z": 1, "type": "ladder" }, { "x": 1, "y": 2, "z": 1, "type": "ladder" }, { "x": 1, "y": 3, "z": 1, "type": "ladder" },
      { "x": 0, "y": 3, "z": 0, "type": "cobblestone" }, { "x": 1, "y": 3, "z": 0, "type": "cobblestone" }, { "x": 2, "y": 3, "z": 0, "type": "cobblestone" },
      { "x": 0, "y": 3, "z": 1, "type": "cobblestone" }, { "x": 2, "y": 3, "z": 1, "type": "cobblestone" },
      { "x": 0, "y": 3, "z": 2, "type": "cobblestone" }, { "x": 1, "y": 3, "z": 2, "type": "cobblestone" }, { "x": 2, "y": 3, "z": 2, "type": "cobblestone" }
    ]
  }
}